<?xml version="1.0" ?>
<!-- =================================================================================== -->
<!-- |    This document was autogenerated by xacro from tm12sx.urdf.xacro              | -->
<!-- |    EDITING THIS FILE BY HAND IS NOT RECOMMENDED                                 | -->
<!-- =================================================================================== -->
<robot name="tm12sx">
  <gazebo reference="link_1">
    <selfCollide>true</selfCollide>
  </gazebo>
  <gazebo reference="link_2">
    <selfCollide>true</selfCollide>
  </gazebo>
  <gazebo reference="link_3">
    <selfCollide>true</selfCollide>
  </gazebo>
  <gazebo reference="link_4">
    <selfCollide>true</selfCollide>
  </gazebo>
  <gazebo reference="link_5">
    <selfCollide>true</selfCollide>
  </gazebo>
  <gazebo reference="link_6">
    <selfCollide>true</selfCollide>
  </gazebo>
  <gazebo>
    <plugin filename="libgazebo_ros_control.so" name="gazebo_ros_control">
      <robotNamespace>/</robotNamespace>
      <robotSimType>gazebo_ros_control/DefaultRobotHWSim</robotSimType>
    </plugin>
  </gazebo>
  <transmission name="trans_1">
    <type>transmission_interface/SimpleTransmission</type>
    <joint name="joint_1">
      <hardwareInterface>hardware_interface/PositionJointInterface</hardwareInterface>
    </joint>
    <actuator name="motor_1">
      <mechanicalReduction>1</mechanicalReduction>
    </actuator>
  </transmission>
  <transmission name="trans_2">
    <type>transmission_interface/SimpleTransmission</type>
    <joint name="joint_2">
      <hardwareInterface>hardware_interface/PositionJointInterface</hardwareInterface>
    </joint>
    <actuator name="motor_2">
      <mechanicalReduction>1</mechanicalReduction>
    </actuator>
  </transmission>
  <transmission name="trans_3">
    <type>transmission_interface/SimpleTransmission</type>
    <joint name="joint_3">
      <hardwareInterface>hardware_interface/PositionJointInterface</hardwareInterface>
    </joint>
    <actuator name="motor_3">
      <mechanicalReduction>1</mechanicalReduction>
    </actuator>
  </transmission>
  <transmission name="trans_4">
    <type>transmission_interface/SimpleTransmission</type>
    <joint name="joint_4">
      <hardwareInterface>hardware_interface/PositionJointInterface</hardwareInterface>
    </joint>
    <actuator name="motor_4">
      <mechanicalReduction>1</mechanicalReduction>
    </actuator>
  </transmission>
  <transmission name="trans_5">
    <type>transmission_interface/SimpleTransmission</type>
    <joint name="joint_5">
      <hardwareInterface>hardware_interface/PositionJointInterface</hardwareInterface>
    </joint>
    <actuator name="motor_5">
      <mechanicalReduction>1</mechanicalReduction>
    </actuator>
  </transmission>
  <transmission name="trans_6">
    <type>transmission_interface/SimpleTransmission</type>
    <joint name="joint_6">
      <hardwareInterface>hardware_interface/PositionJointInterface</hardwareInterface>
    </joint>
    <actuator name="motor_6">
      <mechanicalReduction>1</mechanicalReduction>
    </actuator>
  </transmission>
  <material name="default">
    <color rgba="0.695 0.743 0.790 1.0"/>
  </material>
  <material name="red">
    <color rgba="0.950 0.000 0.000 1.0"/>
  </material>
  <material name="orange">
    <color rgba="1.000 0.500 0.000 1.0"/>
  </material>
  <material name="yellow">
    <color rgba="1.000 1.000 0.000 1.0"/>
  </material>
  <material name="green">
    <color rgba="0.000 1.000 0.000 1.0"/>
  </material>
  <material name="blue">
    <color rgba="0.000 0.000 1.000 1.0"/>
  </material>
  <material name="indigo">
    <color rgba="0.300 0.300 0.600 1.0"/>
  </material>
  <material name="violet">
    <color rgba="0.600 0.000 1.000 1.0"/>
  </material>
  <material name="black">
    <color rgba="0.000 0.000 0.000 1.0"/>
  </material>
  <material name="darkolive">
    <color rgba="0.300 0.300 0.250 1.0"/>
  </material>
  <material name="pebblegray">
    <color rgba="0.706 0.690 0.631 1.0"/>
  </material>
  <material name="grey">
    <color rgba="0.750 0.750 0.750 1.0"/>
  </material>
  <material name="whitegraphite">
    <color rgba="0.773 0.780 0.769 1.0"/>
  </material>
  <material name="graywhite">
    <color rgba="0.839 0.835 0.792 1.0"/>
  </material>
  <material name="purewhite">
    <color rgba="0.941 0.929 0.882 1.0"/>
  </material>
  <material name="white">
    <color rgba="0.950 0.950 0.950 1.0"/>
  </material>
  <material name="gold">
    <color rgba="0.831 0.686 0.218 1.0"/>
  </material>
  <material name="iron">
    <color rgba="0.380 0.400 0.417 1.0"/>
  </material>
  <material name="emeraldgreen">
    <color rgba="0.040 0.455 0.251 1.0"/>
  </material>
  <!--LinkDescription-->
  <link name="link_0">
    <visual>
      <geometry>
        <mesh filename="package://tm_description/meshes/tm12s/visual/tm12s-tbb_a.obj"/>
      </geometry>
      <material name="emeraldgreen"/>
    </visual>
    <collision>
      <geometry>
        <mesh filename="package://tm_description/meshes/tm12s/collision/tm12s-tbb_a_c.stl"/>
      </geometry>
    </collision>
    <inertial>
      <mass value="1.0"/>
      <origin rpy="0.000000 0.000000 0.000000" xyz="0.000000 0.000000 0.000000"/>
      <inertia ixx="0.00110833289" ixy="0.0" ixz="0.0" iyy="0.00110833289" iyz="0.0" izz="0.0018"/>
    </inertial>
  </link>
  <joint name="joint_1" type="revolute">
    <parent link="link_0"/>
    <child link="link_1"/>
    <origin rpy="0.000000 -0.000000 0.000000" xyz="0.000000 0.000000 0.165200"/>
    <axis xyz="0 0 1"/>
    <!--limit-->
    <limit effort="353" lower="-6.283185307179586" upper="6.283185307179586" velocity="2.2689280275926285"/>
    <dynamics damping="0.0" friction="0.0"/>
  </joint>
  <link name="link_1">
    <visual>
      <geometry>
        <mesh filename="package://tm_description/meshes/tm12s/visual/tm12s-j1-a.obj"/>
      </geometry>
      <material name="emeraldgreen"/>
    </visual>
    <collision>
      <geometry>
        <mesh filename="package://tm_description/meshes/tm12s/collision/tm12s-j1-a_c.stl"/>
      </geometry>
    </collision>
    <inertial>
      <origin rpy="0.000000 0.000000 0.000000" xyz="0.000000 0.000000 0.000000"/>
      <mass value="8.2"/>
      <inertia ixx="0.025963078" ixy="0.000000" ixz="0.000000" iyy="0.037671229" iyz="0.000000" izz="0.03885637"/>
    </inertial>
  </link>
  <joint name="joint_2" type="revolute">
    <parent link="link_1"/>
    <child link="link_2"/>
    <origin rpy="-1.570796 -1.570796 0.000000" xyz="0.000000 0.000000 0.000000"/>
    <axis xyz="0 0 1"/>
    <!--limit-->
    <limit effort="353" lower="-6.283185307179586" upper="6.283185307179586" velocity="2.2689280275926285"/>
    <dynamics damping="0.0" friction="0.0"/>
  </joint>
  <link name="link_2">
    <visual>
      <geometry>
        <mesh filename="package://tm_description/meshes/tm12s/visual/tm12s-a1.obj"/>
      </geometry>
      <material name="emeraldgreen"/>
    </visual>
    <collision>
      <geometry>
        <mesh filename="package://tm_description/meshes/tm12s/collision/tm12s-a1_c.stl"/>
      </geometry>
    </collision>
    <inertial>
      <origin rpy="0.000000 0.000000 0.000000" xyz="0.000000 0.000000 0.000000"/>
      <mass value="15.017"/>
      <inertia ixx="0.056178979" ixy="0.000000" ixz="0.000000" iyy="1.2126103999999998" iyz="0.000000" izz="1.2312699999999999"/>
    </inertial>
  </link>
  <joint name="joint_3" type="revolute">
    <parent link="link_2"/>
    <child link="link_3"/>
    <origin rpy="0.000000 -0.000000 0.000000" xyz="0.636100 0.000000 0.000000"/>
    <axis xyz="0 0 1"/>
    <!--limit-->
    <limit effort="157" lower="-2.827433388230814" upper="2.827433388230814" velocity="3.6651914291880923"/>
    <dynamics damping="0.0" friction="0.0"/>
  </joint>
  <link name="link_3">
    <visual>
      <geometry>
        <mesh filename="package://tm_description/meshes/tm12s/visual/tm12s-a2.obj"/>
      </geometry>
      <material name="emeraldgreen"/>
    </visual>
    <collision>
      <geometry>
        <mesh filename="package://tm_description/meshes/tm12s/collision/tm12s-a2_c.stl"/>
      </geometry>
    </collision>
    <inertial>
      <origin rpy="0.000000 0.000000 0.000000" xyz="0.000000 0.000000 0.000000"/>
      <mass value="3.329"/>
      <inertia ixx="0.004694543099999999" ixy="0.000000" ixz="0.000000" iyy="0.13409854" iyz="0.000000" izz="0.13552591"/>
    </inertial>
  </link>
  <joint name="joint_4" type="revolute">
    <parent link="link_3"/>
    <child link="link_4"/>
    <origin rpy="0.000000 -0.000000 1.570796" xyz="0.532400 0.000000 -0.181800"/>
    <axis xyz="0 0 1"/>
    <!--limit-->
    <limit effort="54" lower="-6.283185307179586" upper="6.283185307179586" velocity="3.9269908169872414"/>
    <dynamics damping="0.0" friction="0.0"/>
  </joint>
  <link name="link_4">
    <visual>
      <geometry>
        <mesh filename="package://tm_description/meshes/tm12s/visual/tm12s-j5.obj"/>
      </geometry>
      <material name="emeraldgreen"/>
    </visual>
    <collision>
      <geometry>
        <mesh filename="package://tm_description/meshes/tm12s/collision/tm12s-j5_c.stl"/>
      </geometry>
    </collision>
    <inertial>
      <origin rpy="0.000000 0.000000 0.000000" xyz="0.000000 0.000000 0.000000"/>
      <mass value="1.77"/>
      <inertia ixx="0.0020460318" ixy="0.000000" ixz="0.000000" iyy="0.0031718293" iyz="0.000000" izz="0.0034789517999999995"/>
    </inertial>
  </link>
  <joint name="joint_5" type="revolute">
    <parent link="link_4"/>
    <child link="link_5"/>
    <origin rpy="1.570796 -0.000000 0.000000" xyz="0.000000 -0.131500 0.000000"/>
    <axis xyz="0 0 1"/>
    <!--limit-->
    <limit effort="54" lower="-6.283185307179586" upper="6.283185307179586" velocity="3.9269908169872414"/>
    <dynamics damping="0.0" friction="0.0"/>
  </joint>
  <link name="link_5">
    <visual>
      <geometry>
        <mesh filename="package://tm_description/meshes/tm12s/visual/tm12s-j6.obj"/>
      </geometry>
      <material name="emeraldgreen"/>
    </visual>
    <collision>
      <geometry>
        <mesh filename="package://tm_description/meshes/tm12s/collision/tm12s-j6_c.stl"/>
      </geometry>
    </collision>
    <inertial>
      <origin rpy="0.000000 0.000000 0.000000" xyz="0.000000 0.000000 0.000000"/>
      <mass value="1.77"/>
      <inertia ixx="0.0020460318" ixy="0.000000" ixz="0.000000" iyy="0.0031718293" iyz="0.000000" izz="0.0034789517999999995"/>
    </inertial>
  </link>
  <joint name="joint_6" type="revolute">
    <parent link="link_5"/>
    <child link="link_6"/>
    <origin rpy="1.570796 -0.000000 0.000000" xyz="0.000000 -0.134950 0.000000"/>
    <axis xyz="0 0 1"/>
    <!--limit-->
    <limit effort="34" lower="-6.283185307179586" upper="6.283185307179586" velocity="7.853981633974483"/>
    <dynamics damping="0.0" friction="0.0"/>
  </joint>
  <link name="link_6">
    <visual>
      <geometry>
        <mesh filename="package://tm_description/meshes/tm5s/visual/tm5s-iox.obj"/>
      </geometry>
      <material name="emeraldgreen"/>
    </visual>
    <collision>
      <geometry>
        <mesh filename="package://tm_description/meshes/tm5s/collision/tm5s-iox_c.stl"/>
      </geometry>
    </collision>
    <inertial>
      <origin rpy="0.000000 0.000000 0.000000" xyz="0.000000 0.000000 0.000000"/>
      <mass value="0.34"/>
      <inertia ixx="0.00025085803999999996" ixy="0.000000" ixz="0.000000" iyy="0.00025281701" iyz="0.000000" izz="0.00031221304"/>
    </inertial>
  </link>
  <link name="base"/>
  <joint name="base_fixed_joint" type="fixed">
    <parent link="base"/>
    <child link="link_0"/>
    <origin rpy="0.000000 0.000000 0.000000" xyz="0.000000 0.000000 0.000000"/>
  </joint>
  <link name="flange"/>
  <joint name="flange_fixed_joint" type="fixed">
    <parent link="link_6"/>
    <child link="flange"/>
    <origin rpy="0.000000 0.000000 0.000000" xyz="0.000000 0.000000 0.000000"/>
  </joint>
  <!--LinkDescription-->
</robot>
